<?xml version='1.0'?>
<sdf version='1.4'>
  <model name="thymio">
    <pose>0 0 0 0 0 0</pose>
    <static>false</static>
    <link name='chassis'>
      <pose>0 0 .01 0 0 0</pose>
      <inertial>
        <mass>0.270</mass>
        <inertia>
          <ixx>1.272320e-04</ixx>
          <ixy>-1.138297e-06</ixy>
          <ixz>-1.762013e-21</ixz>
          <iyy>1.260759e-04</iyy>
          <iyz>-2.367320e-23</iyz>
          <izz>2.183003e-04</izz>
        </inertia>
      </inertial>
      <self_collide>True</self_collide>

      <collision name='collision'>
        <pose>0 0 0 0 0 0</pose>
        <geometry>
          <mesh>
            <uri>model://thymio/meshes/thymio.dae</uri>
          </mesh>
        </geometry>
      </collision>

      <visual name='visual'>
        <pose>0 0 0 0 0 0</pose>
        <geometry>
          <mesh>
            <uri>model://thymio/meshes/thymio.dae</uri>
          </mesh>
        </geometry>
      </visual>

      <collision name='caster_collision'>
        <pose>0.045 0 -0.02 0 0 0</pose>
          <geometry>
            <sphere>
              <radius>.01</radius>
            </sphere>
          </geometry>

          <surface>
            <friction>
              <ode>
                <mu>0</mu>
                <mu2>0</mu2>
                <slip1>1.0</slip1>
                <slip2>1.0</slip2>
              </ode>
            </friction>
          </surface>
      </collision>

      <visual name='caster_visual'>
         <!-- <pose>0.045 0 -0.0225 0 0 0</pose> -->
        <pose>0.045 0 -0.02 0 0 0</pose>
          <geometry>
            <sphere>
              <radius>.01</radius>
            </sphere>
          </geometry>
      </visual>

      <collision name='gripper_collision'>
        <pose>0.045 0.085 -0.022 0 0 3.14</pose>
        <geometry>
          <mesh>
            <uri>model://thymio/meshes/gripper.dae</uri>
            <scale>0.1 0.1 0.1</scale>
          </mesh>
        </geometry>
      </collision>

      <visual name='gripper_visual'>
        <pose>0.045 0.085 -0.022 0 0 3.14</pose>
          <geometry>
            <mesh>
              <uri>model://thymio/meshes/gripper.dae</uri>
              <scale>0.1 0.1 0.1</scale>
            </mesh>
          </geometry>
      </visual>

      <collision name='reapberry_visual'>
        <pose>0 0 0.038 0 0 0</pose>
          <geometry>
            <mesh>
              <uri>model://thymio/meshes/raspberry_case.dae</uri>
              <scale>0.11 0.11 0.11</scale>
            </mesh>
          </geometry>
      </collision>

      <visual name='raspberry_visual'>
        <pose>0 0 0.038 0 0 0</pose>
          <geometry>
            <mesh>
              <uri>model://thymio/meshes/raspberry_case.dae</uri>
              <scale>0.11 0.11 0.11</scale>
            </mesh>
          </geometry>
      </visual>

      <!-- <collision name='battery_collision'>
        <pose>0 0 0.05 0 0 0</pose>
          <geometry>
            <mesh>
              <uri>model://thymio/meshes/battery.dae</uri>
              <scale>0.08 0.08 0.08</scale>
            </mesh>
          </geometry>
      </collision>

      <visual name='battery_visual'>
        <pose>0 0 0.05 0 0 0</pose>
          <geometry>
            <mesh>
              <uri>model://thymio/meshes/battery.dae</uri>
              <scale>0.1 0.1 0.1</scale>
            </mesh>
          </geometry>
      </visual> -->

    </link>

    <link name="left_wheel">

      <pose>-0.027 0.05 0 0 1.5707 1.5707</pose>
      <collision name="collision">
        <geometry>
          <cylinder>
            <radius>.02</radius>
            <length>.015</length>
          </cylinder>
        </geometry>
      </collision>

      <visual name="visual">
        <geometry>
          <cylinder>
            <radius>.02</radius>
            <length>.015</length>
          </cylinder>
        </geometry>
      </visual>

    </link>

    <link name="right_wheel">
      <pose>-0.027 -0.05 0 0 1.5707 1.5707</pose>
      <collision name="collision">
        <geometry>
          <cylinder>
            <radius>.02</radius>
            <length>.015</length>
          </cylinder>
        </geometry>
      </collision>

      <visual name="visual">
        <geometry>
          <cylinder>
            <radius>.02</radius>
            <length>.015</length>
          </cylinder>
        </geometry>
      </visual>

    </link>

    <joint type="revolute" name="left_wheel_hinge">
      <pose>0 0 -0.04 0 0 0</pose>
      <child>left_wheel</child>
      <parent>chassis</parent>
      <axis>
        <xyz>0 0 1</xyz>
        <use_parent_model_frame>0</use_parent_model_frame>
          <limit>
            <effort>3.924000e-01</effort>
            <velocity>5.235988e+00</velocity>
          </limit>
      </axis>
    </joint>

    <joint type="revolute" name="right_wheel_hinge">
      <pose>0 0 0.04 0 3.14 0</pose>
      <child>right_wheel</child>
      <parent>chassis</parent>
      <axis>
        <xyz>0 0 1</xyz>
        <use_parent_model_frame>0</use_parent_model_frame>
        <limit>
          <effort>3.924000e-01</effort>
          <velocity>5.235988e+00</velocity>
        </limit>
      </axis>
    </joint>

    <link name="laser_front_link">
      <pose>0.045 0 0 0 0 0</pose>
      <sensor name="laser_front" type="ray">
      <ray>
       <scan>
         <horizontal>
           <samples>640</samples>
           <resolution>1</resolution>
           <min_angle>-0.011111</min_angle>
           <max_angle>0.011111</max_angle>

           <!-- <min_angle>-2.26889</min_angle>
           <max_angle>2.26889</max_angle> -->
         </horizontal>
       </scan>
       <range>
         <min>0.08</min>
         <max>10</max>
         <resolution>0.01</resolution>
       </range>
      </ray>
      <visualize>true</visualize>
      </sensor>
    </link>

    <joint name="laser_front_joint" type="fixed">
      <child>laser_front_link</child>
      <parent>chassis</parent>
    </joint>

    <link name="laser_front_right_link">
      <pose>0.045 -0.015 0 0 0 -0.2617994</pose>
      <sensor name="laser_front_right" type="ray">
      <ray>
       <scan>
         <horizontal>
           <samples>640</samples>
           <resolution>1</resolution>
           <min_angle>-0.011111</min_angle>
           <max_angle>0.011111</max_angle>

           <!-- <min_angle>-2.26889</min_angle>
           <max_angle>2.26889</max_angle> -->
         </horizontal>
       </scan>
       <range>
         <min>0.08</min>
         <max>10</max>
         <resolution>0.01</resolution>
       </range>
      </ray>
      <visualize>true</visualize>
      </sensor>
    </link>

    <joint name="laser_front_right_joint" type="fixed">
      <child>laser_front_right_link</child>
      <parent>chassis</parent>
    </joint>

    <link name="laser_front_left_link">
      <pose>0.045 0.015 0 0 0 0.2617994</pose>
      <sensor name="laser_front_left" type="ray">
      <ray>
       <scan>
         <horizontal>
           <samples>640</samples>
           <resolution>1</resolution>
           <min_angle>-0.011111</min_angle>
           <max_angle>0.011111</max_angle>

           <!-- <min_angle>-2.26889</min_angle>
           <max_angle>2.26889</max_angle> -->
         </horizontal>
       </scan>
       <range>
         <min>0.08</min>
         <max>10</max>
         <resolution>0.01</resolution>
       </range>
      </ray>
      <visualize>true</visualize>
      </sensor>
    </link>

    <joint name="laser_front_left_joint" type="fixed">
      <child>laser_front_left_link</child>
      <parent>chassis</parent>
    </joint>

    <link name="laser_front_right_far_link">
      <pose>0.045 -0.045 0 0 0 -0.5235988</pose>
      <sensor name="laser_front_right_far" type="ray">
      <ray>
       <scan>
         <horizontal>
           <samples>640</samples>
           <resolution>1</resolution>
           <min_angle>-0.011111</min_angle>
           <max_angle>0.011111</max_angle>

           <!-- <min_angle>-2.26889</min_angle>
           <max_angle>2.26889</max_angle> -->
         </horizontal>
       </scan>
       <range>
         <min>0.08</min>
         <max>10</max>
         <resolution>0.01</resolution>
       </range>
      </ray>
      <visualize>true</visualize>
      </sensor>
    </link>

    <joint name="laser_front_right_far_joint" type="fixed">
      <child>laser_front_right_far_link</child>
      <parent>chassis</parent>
    </joint>

    <link name="laser_front_left_far_link">
      <pose>0.045 0.045 0 0 0 0.5235988</pose>
      <sensor name="laser_front_left_far" type="ray">
      <ray>
       <scan>
         <horizontal>
           <samples>640</samples>
           <resolution>1</resolution>
           <min_angle>-0.011111</min_angle>
           <max_angle>0.011111</max_angle>

           <!-- <min_angle>-2.26889</min_angle>
           <max_angle>2.26889</max_angle> -->
         </horizontal>
       </scan>
       <range>
         <min>0.08</min>
         <max>10</max>
         <resolution>0.01</resolution>
       </range>
      </ray>
      <visualize>true</visualize>
      </sensor>
    </link>

    <joint name="laser_front_left_far_joint" type="fixed">
      <child>laser_front_left_far_link</child>
      <parent>chassis</parent>
    </joint>

    <link name="laser_back_right_link">
      <pose>-0.045 -0.045 0 0 0 3.14</pose>
      <sensor name="laser_back_right" type="ray">
      <ray>
       <scan>
         <horizontal>
           <samples>640</samples>
           <resolution>1</resolution>
           <min_angle>-0.011111</min_angle>
           <max_angle>0.011111</max_angle>

           <!-- <min_angle>-2.26889</min_angle>
           <max_angle>2.26889</max_angle> -->
         </horizontal>
       </scan>
       <range>
         <min>0.08</min>
         <max>10</max>
         <resolution>0.01</resolution>
       </range>
      </ray>
      <visualize>true</visualize>
      </sensor>
    </link>

    <joint name="laser_back_right_joint" type="fixed">
      <child>laser_back_right_link</child>
      <parent>chassis</parent>
    </joint>

    <link name="laser_back_left_link">
      <pose>-0.045 0.045 0 0 0 3.14</pose>
      <sensor name="laser_back_left" type="ray">
      <ray>
       <scan>
         <horizontal>
           <samples>640</samples>
           <resolution>1</resolution>
           <min_angle>-0.011111</min_angle>
           <max_angle>0.011111</max_angle>

           <!-- <min_angle>-2.26889</min_angle>
           <max_angle>2.26889</max_angle> -->
         </horizontal>
       </scan>
       <range>
         <min>0.08</min>
         <max>10</max>
         <resolution>0.01</resolution>
       </range>
      </ray>
      <visualize>true</visualize>
      </sensor>
    </link>

    <joint name="laser_back_left_joint" type="fixed">
      <child>laser_back_left_link</child>
      <parent>chassis</parent>
    </joint>

    <plugin name="robot_controller" filename="libtolrobotcontrol.so">
      <rv:robot_config xmlns:rv="https://github.com/ElteHupkes/revolve">
        <rv:update_rate>8.000000e+00</rv:update_rate>

        <rv:brain></rv:brain>
        <rv:motor joint="left_wheel_hinge" type="velocity" max_velocity="5.235988e+00"  min_velocity="-5.235988e+00" id="module3__rotate" part_id="module3"></rv:motor>
        <rv:motor joint="right_wheel_hinge" type="velocity" max_velocity="5.235988e+00"  min_velocity="-5.235988e+00" id="module4__rotate" part_id="module4"></rv:motor>
      </rv:robot_config>
    </plugin>

  </model>
</sdf>
